Workbook

Sheet Budget
A1: Household Budget — October 2026 rebuild
A2: Built from Jan 1–Oct 13, 2026 statements: Bills (…3923), Checking (…4570), Emergency Fund/SPAXX (…1702). Blue = input you can change; black = formula. Targets are proposals — edit column F.
A4: INCOME INPUTS (take-home, all three accounts combined)
A5: Diogo net per paycheck | B5: 9665.75 | C5: Sep 2026 deposits: $4,832.88 (Bills) + $2,899.72 (Checking) + $1,933.15 (SPAXX).
A6: Diogo paychecks per year | B6: 24 | C6: Semi-monthly (14th/15th & 29th/30th pattern in statements).
A7: Allison net per week | B7: 1592.66 | C7: Regular weeks Sep 2026: $796.33 + $477.80 + $318.53. Oct 7 deposit was $1,638.12 (slightly higher) — using the conservative figure.
A8: Allison pay weeks per year | B8: 52 | C8: Weekly pay → 4 months/yr have 5 paychecks; treat the 5th paycheck as bonus money (see Rules).
A9: Monthly take-home (run-rate) | B9: =B5*B6/12+B7*B8/12 -> 26233.027 | C9: Excludes bonus, one-off checks and interest. Config shows household gross $504k.
A11: Line | B11: Account | C11: Type | D11: Q3 avg /mo (actual) | E11: Jan–Sep avg /mo (actual) | F11: TARGET /mo | G11: Δ vs Q3 | H11: Note
A12: BILLS ACCOUNT — fixed obligations on autopay
A13: Mortgage (NewRez) | B13: Bills | C13: Fixed | D13: 6858 | E13: 6858 | F13: 6858 | G13: =F13-D13 -> 0 | H13: Fixed. Escrow status unknown — confirm whether property tax/insurance are inside this payment.
A14: Volvo loan (Metro CU) | B14: Bills | C14: Fixed | D14: 1174 | E14: 1174 | F14: 1174 | G14: =F14-D14 -> 0 | H14: 5.49% per your debt note. Fixed.
A15: Audi loan (Audi Financial) | B15: Bills | C15: Fixed | D15: 1057 | E15: 1057 | F15: 1057 | G15: =F15-D15 -> 0 | H15: 5.25% per your debt note. Fixed.
A16: Synchrony 0% AC loan (HVAC repair) | B16: Bills | C16: Fixed | D16: 342 | E16: 342 | F16: 342 | G16: =F16-D16 -> 0 | H16: 0% for the loan term. ~$9.2k left per your debt note (that note's balance may be older) ≈ 27 payments → ends ~Jan-29. That $342 is freed then (modeled on the Debt & EF Plan sheet).
A17: HELOC — Holyoke CU (10-yr principal+interest, first draw) | B17: Bills | C17: Fixed | D17: 700 | E17: 619 | F17: 1100 | G17: =F17-D17 -> 400 | H17: ~$1,100/mo, fully amortizing over 10 years (per you; repriced 3.5% → 7% at the account anniversary). Fixed — cannot be trimmed, so it is not a lever.
A18: Capital One + TD Retail + OnePay/Sync installment plans | B18: Bills | C18: Fixed | D18: 550 | E18: 606 | F18: 700 | G18: =F18-D18 -> 150 | H18: Capital One ~$350, TD ~$190, OnePay/Sync ~$160 (irregular). Confirm each is a 0% plan and when each ends.
A19: Wells Fargo 0% plumbing loan | B19: Bills | C19: Fixed | D19: 150 | E19: 50 | F19: 450 | G19: =F19-D19 -> 300 | H19: Only ONE payment visible (9/22, $450). Assumed monthly until you tell me otherwise — if it was a one-time payment, the savings engine is $450 higher.
A20: GEICO auto | B20: Bills | C20: Fixed | D20: 819 | E20: 844 | F20: 819 | G20: =F20-D20 -> 0 | H20: ~$9.8k/yr. Get 3 competing quotes before renewal.
A21: MassMutual life | B21: Bills | C21: Fixed | D21: 287 | E21: 287 | F21: 287 | G21: =F21-D21 -> 0
A22: Annual insurance premium sinking (Lincoln National $1,116, Apr) | B22: Bills | C22: Sinking | D22: 0 | E22: 124 | F22: 93 | G22: =F22-D22 -> 93 | H22: One $1,115.93 debit on 4/20 (retry payment). $1,116 ÷ 12.
A23: Heating oil (Petro) | B23: Bills | C23: Fixed | D23: 1251 | E23: 826 | F23: 950 | G23: =F23-D23 -> -301 | H23: Petro ran $614/mo Jan–Jun, $1,856 in Jul, $949 in Aug/Sep. The AC loan is the Synchrony line above, so this is oil/service only (~$11k/yr at $949). What changed in Jul–Sep? Ask Petro to reconcile the budget plan.
A24: Electric (Eversource) | B24: Bills | C24: Fixed | D24: 372 | E24: 267 | F24: 300 | G24: =F24-D24 -> -72 | H24: Seasonal ($134–$423).
A25: Water + trash (Sudbury Water, Win Waste) | B25: Bills | C25: Fixed | D25: 125 | E25: 141 | F25: 140 | G25: =F25-D25 -> 15 | H25: Quarterly bills; Oct billed $354 + $204.
A26: Verizon wireless + Verizon recurring | B26: Bills | C26: Fixed | D26: 353 | E26: 409 | F26: 347 | G26: =F26-D26 -> -6 | H26: Wireless ~$257 (down from $311) + $90 recurring on checking. Audit lines/plan.
A27: SiriusXM + WGBH + E-ZPass | B27: Bills | C27: Fixed | D27: 125 | E27: 142 | F27: 125 | G27: =F27-D27 -> 0 | H27: SiriusXM ($72.97) is staying. No change vs. Q3.
A28: Landscape, pest/tick, pet waste (Lynch, F&W, Ohdeer, MetroWest) | B28: Bills | C28: Variable | D28: 886 | E28: 619 | F28: 600 | G28: =F28-D28 -> -286 | H28: Lynch is lumpy: $1,275 (Mar) + $1,792 (Sep). Averaged.
A29: Bills account — monthly funding needed | D29: =SUM(D13:D28) -> 15049 | E29: =SUM(E13:E28) -> 14365 | F29: =SUM(F13:F28) -> 15342 | G29: =SUM(G13:G28) -> 293
A31: CHECKING — everyday spending (debit card only; no card charges)
A32: Groceries (Market Basket, Roche Bros, etc.) | B32: Checking | C32: Variable | D32: 844 | E32: 733 | F32: 1050 | G32: =F32-D32 -> 206 | H32: Debit-card groceries jumped from ~$220/mo (Jan–Apr) to ~$1,130/mo (May–Sep) — spend moved from cards to debit in May. True run-rate is ~$1,050. ≈ $242/week.
A33: Dining out + coffee/treats | B33: Checking | C33: Joy | D33: 828 | E33: 965 | F33: 750 | G33: =F33-D33 -> -78 | H33: Protected. Q3 includes beach-week food. Dining + takeout together = $1,050/mo ($242/wk) vs $1,138 in Q3.
A34: Takeout orders (DoorDash, Grubhub) | B34: Checking | C34: Joy | D34: 310 | E34: 325 | F34: 300 | G34: =F34-D34 -> -10 | H34: Family takeout — protected, essentially held at Q3. Only lever: pickup instead of delivery when the fee/tip is the difference.
A35: Cleaning help ($160/wk checks) + Venmo | B35: Checking | C35: Fixed | D35: 761 | E35: 952 | F35: 760 | G35: =F35-D35 -> -1 | H35: $160 × 52 ÷ 12 = $693/mo; Q3 checks averaged $698. Venmo ~$65/mo.
A36: Cleaning/laundry (FreshNClean, Galicia) | B36: Checking | C36: Variable | D36: 58 | E36: 74 | F36: 75 | G36: =F36-D36 -> 17
A37: Gas (fuel stations) | B37: Checking | C37: Variable | D37: 334 | E37: 279 | F37: 340 | G37: =F37-D37 -> 6 | H37: Q3 $334/mo ≈ $77/wk.
A38: Auto upkeep, parking, tolls, RMV (Sudbury Automotive, Audi service) | B38: Checking | C38: Variable | D38: 278 | E38: 274 | F38: 210 | G38: =F38-D38 -> -68 | H38: Lumpy — monthly envelope, not weekly.
A39: Home improvement/garden (Lowe's, Home Depot, Mahoney's, Aubuchon) | B39: Checking | C39: Variable | D39: 363 | E39: 464 | F39: 300 | G39: =F39-D39 -> -63 | H39: Spiked May/Jun ($1.5k/$1.4k) and Sep ($785). Plan projects, then cap.
A40: Thoreau Club | B40: Checking | C40: Joy | D40: 498 | E40: 499 | F40: 498 | G40: =F40-D40 -> 0 | H40: Protected. Largest single discretionary line ($5,976/yr) — decide yearly on cost-per-visit, not monthly.
A41: Kids activities/lessons (AMM Martial Arts, YMCA, music, Paddle Boston) | B41: Checking | C41: Joy | D41: 493 | E41: 483 | F41: 490 | G41: =F41-D41 -> -3 | H41: Protected.
A42: Kids allowance (Greenlight) | B42: Checking | C42: Variable | D42: 207 | E42: 139 | F42: 200 | G42: =F42-D42 -> -7 | H42: Move to a fixed weekly allowance instead of ad-hoc $20 reloads.
A43: Kids digital: Apple.com/bill + Nintendo/PlayStation | B43: Checking | C43: Variable | D43: 870 | E43: 478 | F43: 350 | G43: =F43-D43 -> -520 | H43: Biggest overrun vs. trend: $870/mo in Q3 vs ~$280 in H1 (Aug: $1,331). Check Apple purchase history; turn on Ask to Buy; fund with prepaid gift cards.
...

Sheet Weekly Envelopes
A1: Weekly envelopes — Checking account (debit card)
A2: Weekly = monthly target × 12 ÷ 52. Targets come from the Budget sheet (green = link), so edit them there. 'Q3 /wk' = what you actually spent in Jul–Sep.
A4: Envelope (spend-as-you-go) | B4: Monthly target | C4: WEEKLY target | D4: Q3 actual /wk | E4: Δ /wk vs Q3 | F4: Jan–Sep avg /wk
A5: Groceries | B5: =Budget!F32 -> 1050 | C5: =B5*12/52 -> 242.30769 | D5: =Budget!D32*12/52 -> 194.76923 | E5: =C5-D5 -> 47.538462 | F5: =Budget!E32*12/52 -> 169.15385
A6: Dining out + coffee/treats | B6: =Budget!F33 -> 750 | C6: =B6*12/52 -> 173.07692 | D6: =Budget!D33*12/52 -> 191.07692 | E6: =C6-D6 -> -18 | F6: =Budget!E33*12/52 -> 222.69231
A7: Takeout (DoorDash, Grubhub) | B7: =Budget!F34 -> 300 | C7: =B7*12/52 -> 69.230769 | D7: =Budget!D34*12/52 -> 71.538462 | E7: =C7-D7 -> -2.3076923 | F7: =Budget!E34*12/52 -> 75
A8: Gas | B8: =Budget!F37 -> 340 | C8: =B8*12/52 -> 78.461538 | D8: =Budget!D37*12/52 -> 77.076923 | E8: =C8-D8 -> 1.3846154 | F8: =Budget!E37*12/52 -> 64.384615
A9: Amazon + household orders | B9: =Budget!F46 -> 500 | C9: =B9*12/52 -> 115.38462 | D9: =Budget!D46*12/52 -> 181.15385 | E9: =C9-D9 -> -65.769231 | F9: =Budget!E46*12/52 -> 235.84615
A10: Kids allowance (Greenlight) | B10: =Budget!F42 -> 200 | C10: =B10*12/52 -> 46.153846 | D10: =Budget!D42*12/52 -> 47.769231 | E10: =C10-D10 -> -1.6153846 | F10: =Budget!E42*12/52 -> 32.076923
A11: Fun money (movies, hobbies, cash) | B11: =Budget!F45 -> 300 | C11: =B11*12/52 -> 69.230769 | D11: =Budget!D45*12/52 -> 68.307692 | E11: =C11-D11 -> 0.92307692 | F11: =Budget!E45*12/52 -> 67.615385
A12: Spend-as-you-go total | B12: =SUM(B5:B11) -> 3440 | C12: =SUM(C5:C11) -> 793.84615 | D12: =SUM(D5:D11) -> 831.69231 | E12: =SUM(E5:E11) -> -37.846154 | F12: =SUM(F5:F11) -> 866.76923
A14: Planned / lumpy — handle monthly, not weekly
A15: Line | B15: Monthly target | C15: Per week equivalent | D15: Q3 actual /wk
A16: Cleaning help ($160/wk checks) + Venmo | B16: =Budget!F35 -> 760 | C16: =B16*12/52 -> 175.38462 | D16: =Budget!D35*12/52 -> 175.61538
A17: Cleaning/laundry (FreshNClean, Galicia) | B17: =Budget!F36 -> 75 | C17: =B17*12/52 -> 17.307692 | D17: =Budget!D36*12/52 -> 13.384615
A18: Auto upkeep, parking, tolls, RMV (Sudbury Automotive, Audi service) | B18: =Budget!F38 -> 210 | C18: =B18*12/52 -> 48.461538 | D18: =Budget!D38*12/52 -> 64.153846
A19: Home improvement/garden (Lowe's, Home Depot, Mahoney's, Aubuchon) | B19: =Budget!F39 -> 300 | C19: =B19*12/52 -> 69.230769 | D19: =Budget!D39*12/52 -> 83.769231
A20: Thoreau Club | B20: =Budget!F40 -> 498 | C20: =B20*12/52 -> 114.92308 | D20: =Budget!D40*12/52 -> 114.92308
A21: Kids activities/lessons (AMM Martial Arts, YMCA, music, Paddle Boston) | B21: =Budget!F41 -> 490 | C21: =B21*12/52 -> 113.07692 | D21: =Budget!D41*12/52 -> 113.76923
A22: Kids digital: Apple.com/bill + Nintendo/PlayStation | B22: =Budget!F43 -> 350 | C22: =B22*12/52 -> 80.769231 | D22: =Budget!D43*12/52 -> 200.76923
A23: Kids STEM/craft boxes (CrunchLabs, Raddish) | B23: =Budget!F44 -> 50 | C23: =B23*12/52 -> 11.538462 | D23: =Budget!D44*12/52 -> 21.461538
A24: Clothing/shoes | B24: =Budget!F47 -> 250 | C24: =B24*12/52 -> 57.692308 | D24: =Budget!D47*12/52 -> 64.615385
A25: Personal care (salon, barber) | B25: =Budget!F48 -> 100 | C25: =B25*12/52 -> 23.076923 | D25: =Budget!D48*12/52 -> 23.307692
A26: Health/pharmacy/vet | B26: =Budget!F49 -> 75 | C26: =B26*12/52 -> 17.307692 | D26: =Budget!D49*12/52 -> 14.538462
A27: Streaming/audio/video subscriptions | B27: =Budget!F50 -> 170 | C27: =B27*12/52 -> 39.230769 | D27: =Budget!D50*12/52 -> 58.153846
A28: News/info subscriptions | B28: =Budget!F51 -> 90 | C28: =B28*12/52 -> 20.769231 | D28: =Budget!D51*12/52 -> 35.307692
A29: Tools/software/professional (GitHub, Claude, Whoop, Ring, Calendly…) | B29: =Budget!F52 -> 240 | C29: =B29*12/52 -> 55.384615 | D29: =Budget!D52*12/52 -> 55.384615
A30: Donations/advocacy | B30: =Budget!F53 -> 75 | C30: =B30*12/52 -> 17.307692 | D30: =Budget!D53*12/52 -> 8.7692308
A31: Fees/taxes/professional | B31: =Budget!F54 -> 115 | C31: =B31*12/52 -> 26.538462 | D31: =Budget!D54*12/52 -> 27
A32: Misc/unclassified buffer | B32: =Budget!F55 -> 150 | C32: =B32*12/52 -> 34.615385 | D32: =Budget!D55*12/52 -> 36.692308
A33: Planned / lumpy total | B33: =SUM(B16:B32) -> 3998 | C33: =SUM(C16:C32) -> 922.61538 | D33: =SUM(D16:D32) -> 1111.6154
A35: EVERYTHING in Checking, per week | B35: =B12+B33 -> 7438 | C35: =C12+C33 -> 1716.4615 | D35: =D12+D33 -> 1943.3077 | E35: Check: equals Budget Checking subtotal ÷ 52 × 12
A36: Check vs Budget subtotal (should be 0) | B36: =B35-Budget!F56 -> 0
A38: Months with a 5th Allison paycheck (2026: Apr, Jul, Sep, Dec) are paid 52/12 — the 5th check is NOT envelope money; it goes to card paydown.

Sheet Debt & EF Plan
A1: Card payoff (avalanche) and emergency-fund timeline
A2: Avalanche = highest APR first. All paydown dollars come from the Budget sheet. Balances as of 9/27 per your config; APRs from your '💳 Debt consolidation' note. Estimates — replace with live statement figures.
A4: Input | B4: Value | C4: Source / note | E4: Result | G4: Read-out
A5: JetBlue (Barclay) balance | B5: 9800.78 | C5: Config debt tracker, 9/27/2026. | E5: JetBlue cleared | G5: =IFERROR(INDEX(A29:A76,MATCH(1,Q29:Q76,0)),"after Oct-30") -> 46508
A6: JetBlue APR | B6: 0.2974 | C6: Debt consolidation note. | E6: Fidelity cleared | G6: =IFERROR(INDEX(A29:A76,MATCH(1,R29:R76,0)),"after Oct-30") -> 46569
A7: Fidelity (Elan) balance | B7: 5341.52 | C7: Config debt tracker, 9/27/2026. | E7: All cards cleared | G7: =IFERROR(INDEX(A29:A76,MATCH(1,S29:S76,0)),"after Oct-30") -> 46569
A8: Fidelity APR | B8: 0.1749 | C8: Debt consolidation note. | E8: EF cash reaches the cash floor | G8: =IFERROR(INDEX(A29:A76,MATCH(1,T29:T76,0)),"after Oct-30") -> 47027
A9: Fidelity minimum rule: % of balance on top of interest | B9: 0.01 | C9: Assumption (typical issuer formula) — not from a statement. | E9: EF total reaches the 6-month cap | G9: =IFERROR(INDEX(A29:A76,MATCH(1,U29:U76,0)),"after Oct-30") -> 47423
A10: Emergency fund — cash now (SPAXX + lifestyle) | B10: 12081 | C10: Config, 9/27/2026 (flagged CHECK as stale). | E10: Card interest paid from Nov-26 on | G10: =SUM(F29:F76)+SUM(J29:J76) -> 1642.6528
A11: EF cap: months of expenses | B11: 6 | C11: Your rule: the EF is capped at 6 months of expenses, held as cash + stock investments. | E11: Interest drag today (/mo, both cards) | G11: =$B$5*$B$6/12+$B$7*$B$8/12 -> 320.74865
A12: Expense basis (1 = essentials, 2 = full budget) | B12: 1 | C12: 1 = Bills account + groceries + gas + pharmacy. 2 = everything in Bills + Checking. Your call — I defaulted to essentials. | E12: Not modeled: new card charges (plan assumes zero), end dates of the Capital One/TD/OnePay/Wells plans (assumed to continue), stock growth, EF interest (~4% on SPAXX), Oct payments.
A13: Essential monthly expenses | B13: =Budget!F29+Budget!F32+Budget!F37+Budget!F49 -> 16807 | C13: Link to Budget targets.
A14: Full budget monthly expenses | B14: =Budget!F29+Budget!F56 -> 22780 | C14: Link to Budget targets.
A15: EF cap ($) | B15: =$B$11*IF($B$12=1,$B$13,$B$14) -> 100842 | C15: Months × chosen expense basis.
A16: Stock investments earmarked as EF — market value | B16: 21681 | C16: Config brokerage_total (flagged stale): QQQ, SMH, VXUS, XBI. Replace with today's value; the Waymark-managed account is NOT counted.
A17: Haircut on stocks (drawdown + tax) | B17: 0.25 | C17: Assumption. Stocks are worth least in the year you need them, and sales trigger tax (23.8% on long-term gains).
A18: Stocks counted toward EF | B18: =$B$16*(1-$B$17) -> 16260.75 | C18: Market value × (1 − haircut). Held flat — no growth assumed.
A19: Cash floor inside the cap (months of essentials) | B19: 3 | C19: Assumption: at least half the cap sits in cash/SPAXX. Your call.
A20: Cash floor ($) | B20: =$B$19*$B$13 -> 50421 | C20: Months × essentials.
A21: Phase 1 ends after | B21: 46419 | C21: Patriots tickets paid in Feb.
A22: Bonus/extra lump (net) — scenario | B22: 0 | C22: Base case $0. Mar 2026 net bonus deposit was ≈ $38.9k — NOT assumed.
A23: Bonus lump lands in month | B23: 46447
A24: Synchrony 0% AC loan — last payment month | B24: 47119 | C24: Estimate: $9,167 ÷ $342 ≈ 27 payments from Nov-26. Debt-note balance may be stale.
A25: Synchrony payment freed once it ends | B25: =Budget!F16 -> 342 | C25: Link to Budget.
A28: Month | B28: Phase paydown | C28: Bonus lump | D28: Total available | E28: JetBlue begin | F28: JetBlue interest | G28: JetBlue payment | H28: JetBlue end | I28: Fidelity begin | J28: Fidelity interest | K28: Fidelity min | L28: Fidelity payment | M28: Fidelity end | N28: EF cash begin | O28: EF contribution (to cap) | P28: EF cash end | Q28: JB cleared | R28: FI cleared | S28: Cards cleared | T28: Cash ≥ floor | U28: EF total ≥ cap | V28: Overflow after cap | W28: EF total (cash + stocks)
A29: 46327 | B29: =IF(A29<=$B$21,Budget!$F$70,Budget!$F$71)+IF(A29>$B$24,$B$25,0) -> 1426.7767 | C29: =IF(A29=$B$23,$B$22,0) -> 0 | D29: =B29+C29 -> 1426.7767 | E29: =$B$5 -> 9800.78 | F29: =E29*$B$6/12 -> 242.896 | G29: =MIN(E29+F29,MAX(D29-K29,0)) -> 1295.5088 | H29: =E29+F29-G29 -> 8748.1672 | I29: =$B$7 -> 5341.52 | J29: =I29*$B$8/12 -> 77.852654 | K29: =MIN(I29+J29,J29+$B$9*I29) -> 131.26785 | L29: =MIN(I29+J29,D29-G29) -> 131.26785 | M29: =I29+J29-L29 -> 5288.1048 | N29: =$B$10 -> 12081 | O29: =MIN(MAX(D29-G29-L29,0),MAX($B$15-$B$18-N29,0)) -> 0 | P29: =N29+O29 -> 12081 | Q29: =IF(H29<=0.005,1,0) -> 0 | R29: =IF(M29<=0.005,1,0) -> 0 | S29: =IF(AND(Q29=1,R29=1),1,0) -> 0 | T29: =IF(P29>=$B$20,1,0) -> 0 | U29: =IF(P29+$B$18>=$B$15-0.5,1,0) -> 0 | V29: =MAX(D29-G29-L29,0)-O29 -> 0 | W29: =P29+$B$18 -> 28341.75
A30: 46357 | B30: =IF(A30<=$B$21,Budget!$F$70,Budget!$F$71)+IF(A30>$B$24,$B$25,0) -> 1426.7767 | C30: =IF(A30=$B$23,$B$22,0) -> 0 | D30: =B30+C30 -> 1426.7767 | E30: =H29 -> 8748.1672 | F30: =E30*$B$6/12 -> 216.80874 | G30: =MIN(E30+F30,MAX(D30-K30,0)) -> 1296.8215 | H30: =E30+F30-G30 -> 7668.1544 | I30: =M29 -> 5288.1048 | J30: =I30*$B$8/12 -> 77.074127 | K30: =MIN(I30+J30,J30+$B$9*I30) -> 129.95518 | L30: =MIN(I30+J30,D30-G30) -> 129.95518 | M30: =I30+J30-L30 -> 5235.2238 | N30: =P29 -> 12081 | O30: =MIN(MAX(D30-G30-L30,0),MAX($B$15-$B$18-N30,0)) -> 0 | P30: =N30+O30 -> 12081 | Q30: =IF(H30<=0.005,1,0) -> 0 | R30: =IF(M30<=0.005,1,0) -> 0 | S30: =IF(AND(Q30=1,R30=1),1,0) -> 0 | T30: =IF(P30>=$B$20,1,0) -> 0 | U30: =IF(P30+$B$18>=$B$15-0.5,1,0) -> 0 | V30: =MAX(D30-G30-L30,0)-O30 -> 0 | W30: =P30+$B$18 -> 28341.75
A31: 46388 | B31: =IF(A31<=$B$21,Budget!$F$70,Budget!$F$71)+IF(A31>$B$24,$B$25,0) -> 1426.7767 | C31: =IF(A31=$B$23,$B$22,0) -> 0 | D31: =B31+C31 -> 1426.7767 | E31: =H30 -> 7668.1544 | F31: =E31*$B$6/12 -> 190.04243 | G31: =MIN(E31+F31,MAX(D31-K31,0)) -> 1298.121 | H31: =E31+F31-G31 -> 6560.0758 | I31: =M30 -> 5235.2238 | J31: =I31*$B$8/12 -> 76.303386 | K31: =MIN(I31+J31,J31+$B$9*I31) -> 128.65562 | L31: =MIN(I31+J31,D31-G31) -> 128.65562 | M31: =I31+J31-L31 -> 5182.8715 | N31: =P30 -> 12081 | O31: =MIN(MAX(D31-G31-L31,0),MAX($B$15-$B$18-N31,0)) -> 0 | P31: =N31+O31 -> 12081 | Q31: =IF(H31<=0.005,1,0) -> 0 | R31: =IF(M31<=0.005,1,0) -> 0 | S31: =IF(AND(Q31=1,R31=1),1,0) -> 0 | T31: =IF(P31>=$B$20,1,0) -> 0 | U31: =IF(P31+$B$18>=$B$15-0.5,1,0) -> 0 | V31: =MAX(D31-G31-L31,0)-O31 -> 0 | W31: =P31+$B$18 -> 28341.75
A32: 46419 | B32: =IF(A32<=$B$21,Budget!$F$70,Budget!$F$71)+IF(A32>$B$24,$B$25,0) -> 1426.7767 | C32: =IF(A32=$B$23,$B$22,0) -> 0 | D32: =B32+C32 -> 1426.7767 | E32: =H31 -> 6560.0758 | F32: =E32*$B$6/12 -> 162.58055 | G32: =MIN(E32+F32,MAX(D32-K32,0)) -> 1299.4076 | H32: =E32+F32-G32 -> 5423.2488 | I32: =M31 -> 5182.8715 | J32: =I32*$B$8/12 -> 75.540352 | K32: =MIN(I32+J32,J32+$B$9*I32) -> 127.36907 | L32: =MIN(I32+J32,D32-G32) -> 127.36907 | M32: =I32+J32-L32 -> 5131.0428 | N32: =P31 -> 12081 | O32: =MIN(MAX(D32-G32-L32,0),MAX($B$15-$B$18-N32,0)) -> 0 | P32: =N32+O32 -> 12081 | Q32: =IF(H32<=0.005,1,0) -> 0 | R32: =IF(M32<=0.005,1,0) -> 0 | S32: =IF(AND(Q32=1,R32=1),1,0) -> 0 | T32: =IF(P32>=$B$20,1,0) -> 0 | U32: =IF(P32+$B$18>=$B$15-0.5,1,0) -> 0 | V32: =MAX(D32-G32-L32,0)-O32 -> 0 | W32: =P32+$B$18 -> 28341.75
A33: 46447 | B33: =IF(A33<=$B$21,Budget!$F$70,Budget!$F$71)+IF(A33>$B$24,$B$25,0) -> 2503.0267 | C33: =IF(A33=$B$23,$B$22,0) -> 0 | D33: =B33+C33 -> 2503.0267 | E33: =H32 -> 5423.2488 | F33: =E33*$B$6/12 -> 134.40618 | G33: =MIN(E33+F33,MAX(D33-K33,0)) -> 2376.9313 | H33: =E33+F33-G33 -> 3180.7237 | I33: =M32 -> 5131.0428 | J33: =I33*$B$8/12 -> 74.784949 | K33: =MIN(I33+J33,J33+$B$9*I33) -> 126.09538 | L33: =MIN(I33+J33,D33-G33) -> 126.09538 | M33: =I33+J33-L33 -> 5079.7324 | N33: =P32 -> 12081 | O33: =MIN(MAX(D33-G33-L33,0),MAX($B$15-$B$18-N33,0)) -> 0 | P33: =N33+O33 -> 12081 | Q33: =IF(H33<=0.005,1,0) -> 0 | R33: =IF(M33<=0.005,1,0) -> 0 | S33: =IF(AND(Q33=1,R33=1),1,0) -> 0 | T33: =IF(P33>=$B$20,1,0) -> 0 | U33: =IF(P33+$B$18>=$B$15-0.5,1,0) -> 0 | V33: =MAX(D33-G33-L33,0)-O33 -> 0 | W33: =P33+$B$18 -> 28341.75
A34: 46478 | B34: =IF(A34<=$B$21,Budget!$F$70,Budget!$F$71)+IF(A34>$B$24,$B$25,0) -> 2503.0267 | C34: =IF(A34=$B$23,$B$22,0) -> 0 | D34: =B34+C34 -> 2503.0267 | E34: =H33 -> 3180.7237 | F34: =E34*$B$6/12 -> 78.828935 | G34: =MIN(E34+F34,MAX(D34-K34,0)) -> 2378.1922 | H34: =E34+F34-G34 -> 881.36035 | I34: =M33 -> 5079.7324 | J34: =I34*$B$8/12 -> 74.037099 | K34: =MIN(I34+J34,J34+$B$9*I34) -> 124.83442 | L34: =MIN(I34+J34,D34-G34) -> 124.83442 | M34: =I34+J34-L34 -> 5028.935 | N34: =P33 -> 12081 | O34: =MIN(MAX(D34-G34-L34,0),MAX($B$15-$B$18-N34,0)) -> 0 | P34: =N34+O34 -> 12081 | Q34: =IF(H34<=0.005,1,0) -> 0 | R34: =IF(M34<=0.005,1,0) -> 0 | S34: =IF(AND(Q34=1,R34=1),1,0) -> 0 | T34: =IF(P34>=$B$20,1,0) -> 0 | U34: =IF(P34+$B$18>=$B$15-0.5,1,0) -> 0 | V34: =MAX(D34-G34-L34,0)-O34 -> 0 | W34: =P34+$B$18 -> 28341.75
A35: 46508 | B35: =IF(A35<=$B$21,Budget!$F$70,Budget!$F$71)+IF(A35>$B$24,$B$25,0) -> 2503.0267 | C35: =IF(A35=$B$23,$B$22,0) -> 0 | D35: =B35+C35 -> 2503.0267 | E35: =H34 -> 881.36035 | F35: =E35*$B$6/12 -> 21.843047 | G35: =MIN(E35+F35,MAX(D35-K35,0)) -> 903.2034 | H35: =E35+F35-G35 -> 0 | I35: =M34 -> 5028.935 | J35: =I35*$B$8/12 -> 73.296728 | K35: =MIN(I35+J35,J35+$B$9*I35) -> 123.58608 | L35: =MIN(I35+J35,D35-G35) -> 1599.8233 | M35: =I35+J35-L35 -> 3502.4085 | N35: =P34 -> 12081 | O35: =MIN(MAX(D35-G35-L35,0),MAX($B$15-$B$18-N35,0)) -> 0 | P35: =N35+O35 -> 12081 | Q35: =IF(H35<=0.005,1,0) -> 1 | R35: =IF(M35<=0.005,1,0) -> 0 | S35: =IF(AND(Q35=1,R35=1),1,0) -> 0 | T35: =IF(P35>=$B$20,1,0) -> 0 | U35: =IF(P35+$B$18>=$B$15-0.5,1,0) -> 0 | V35: =MAX(D35-G35-L35,0)-O35 -> 0 | W35: =P35+$B$18 -> 28341.75
A36: 46539 | B36: =IF(A36<=$B$21,Budget!$F$70,Budget!$F$71)+IF(A36>$B$24,$B$25,0) -> 2503.0267 | C36: =IF(A36=$B$23,$B$22,0) -> 0 | D36: =B36+C36 -> 2503.0267 | E36: =H35 -> 0 | F36: =E36*$B$6/12 -> 0 | G36: =MIN(E36+F36,MAX(D36-K36,0)) -> 0 | H36: =E36+F36-G36 -> 0 | I36: =M35 -> 3502.4085 | J36: =I36*$B$8/12 -> 51.047604 | K36: =MIN(I36+J36,J36+$B$9*I36) -> 86.071689 | L36: =MIN(I36+J36,D36-G36) -> 2503.0267 | M36: =I36+J36-L36 -> 1050.4294 | N36: =P35 -> 12081 | O36: =MIN(MAX(D36-G36-L36,0),MAX($B$15-$B$18-N36,0)) -> 0 | P36: =N36+O36 -> 12081 | Q36: =IF(H36<=0.005,1,0) -> 1 | R36: =IF(M36<=0.005,1,0) -> 0 | S36: =IF(AND(Q36=1,R36=1),1,0) -> 0 | T36: =IF(P36>=$B$20,1,0) -> 0 | U36: =IF(P36+$B$18>=$B$15-0.5,1,0) -> 0 | V36: =MAX(D36-G36-L36,0)-O36 -> 0 | W36: =P36+$B$18 -> 28341.75
A37: 46569 | B37: =IF(A37<=$B$21,Budget!$F$70,Budget!$F$71)+IF(A37>$B$24,$B$25,0) -> 2503.0267 | C37: =IF(A37=$B$23,$B$22,0) -> 0 | D37: =B37+C37 -> 2503.0267 | E37: =H36 -> 0 | F37: =E37*$B$6/12 -> 0 | G37: =MIN(E37+F37,MAX(D37-K37,0)) -> 0 | H37: =E37+F37-G37 -> 0 | I37: =M36 -> 1050.4294 | J37: =I37*$B$8/12 -> 15.310009 | K37: =MIN(I37+J37,J37+$B$9*I37) -> 25.814304 | L37: =MIN(I37+J37,D37-G37) -> 1065.7395 | M37: =I37+J37-L37 -> 0 | N37: =P36 -> 12081 | O37: =MIN(MAX(D37-G37-L37,0),MAX($B$15-$B$18-N37,0)) -> 1437.2872 | P37: =N37+O37 -> 13518.287 | Q37: =IF(H37<=0.005,1,0) -> 1 | R37: =IF(M37<=0.005,1,0) -> 1 | S37: =IF(AND(Q37=1,R37=1),1,0) -> 1 | T37: =IF(P37>=$B$20,1,0) -> 0 | U37: =IF(P37+$B$18>=$B$15-0.5,1,0) -> 0 | V37: =MAX(D37-G37-L37,0)-O37 -> 0 | W37: =P37+$B$18 -> 29779.037
A38: 46600 | B38: =IF(A38<=$B$21,Budget!$F$70,Budget!$F$71)+IF(A38>$B$24,$B$25,0) -> 2503.0267 | C38: =IF(A38=$B$23,$B$22,0) -> 0 | D38: =B38+C38 -> 2503.0267 | E38: =H37 -> 0 | F38: =E38*$B$6/12 -> 0 | G38: =MIN(E38+F38,MAX(D38-K38,0)) -> 0 | H38: =E38+F38-G38 -> 0 | I38: =M37 -> 0 | J38: =I38*$B$8/12 -> 0 | K38: =MIN(I38+J38,J38+$B$9*I38) -> 0 | L38: =MIN(I38+J38,D38-G38) -> 0 | M38: =I38+J38-L38 -> 0 | N38: =P37 -> 13518.287 | O38: =MIN(MAX(D38-G38-L38,0),MAX($B$15-$B$18-N38,0)) -> 2503.0267 | P38: =N38+O38 -> 16021.314 | Q38: =IF(H38<=0.005,1,0) -> 1 | R38: =IF(M38<=0.005,1,0) -> 1 | S38: =IF(AND(Q38=1,R38=1),1,0) -> 1 | T38: =IF(P38>=$B$20,1,0) -> 0 | U38: =IF(P38+$B$18>=$B$15-0.5,1,0) -> 0 | V38: =MAX(D38-G38-L38,0)-O38 -> 0 | W38: =P38+$B$18 -> 32282.064
A39: 46631 | B39: =IF(A39<=$B$21,Budget!$F$70,Budget!$F$71)+IF(A39>$B$24,$B$25,0) -> 2503.0267 | C39: =IF(A39=$B$23,$B$22,0) -> 0 | D39: =B39+C39 -> 2503.0267 | E39: =H38 -> 0 | F39: =E39*$B$6/12 -> 0 | G39: =MIN(E39+F39,MAX(D39-K39,0)) -> 0 | H39: =E39+F39-G39 -> 0 | I39: =M38 -> 0 | J39: =I39*$B$8/12 -> 0 | K39: =MIN(I39+J39,J39+$B$9*I39) -> 0 | L39: =MIN(I39+J39,D39-G39) -> 0 | M39: =I39+J39-L39 -> 0 | N39: =P38 -> 16021.314 | O39: =MIN(MAX(D39-G39-L39,0),MAX($B$15-$B$18-N39,0)) -> 2503.0267 | P39: =N39+O39 -> 18524.341 | Q39: =IF(H39<=0.005,1,0) -> 1 | R39: =IF(M39<=0.005,1,0) -> 1 | S39: =IF(AND(Q39=1,R39=1),1,0) -> 1 | T39: =IF(P39>=$B$20,1,0) -> 0 | U39: =IF(P39+$B$18>=$B$15-0.5,1,0) -> 0 | V39: =MAX(D39-G39-L39,0)-O39 -> 0 | W39: =P39+$B$18 -> 34785.091
A40: 46661 | B40: =IF(A40<=$B$21,Budget!$F$70,Budget!$F$71)+IF(A40>$B$24,$B$25,0) -> 2503.0267 | C40: =IF(A40=$B$23,$B$22,0) -> 0 | D40: =B40+C40 -> 2503.0267 | E40: =H39 -> 0 | F40: =E40*$B$6/12 -> 0 | G40: =MIN(E40+F40,MAX(D40-K40,0)) -> 0 | H40: =E40+F40-G40 -> 0 | I40: =M39 -> 0 | J40: =I40*$B$8/12 -> 0 | K40: =MIN(I40+J40,J40+$B$9*I40) -> 0 | L40: =MIN(I40+J40,D40-G40) -> 0 | M40: =I40+J40-L40 -> 0 | N40: =P39 -> 18524.341 | O40: =MIN(MAX(D40-G40-L40,0),MAX($B$15-$B$18-N40,0)) -> 2503.0267 | P40: =N40+O40 -> 21027.367 | Q40: =IF(H40<=0.005,1,0) -> 1 | R40: =IF(M40<=0.005,1,0) -> 1 | S40: =IF(AND(Q40=1,R40=1),1,0) -> 1 | T40: =IF(P40>=$B$20,1,0) -> 0 | U40: =IF(P40+$B$18>=$B$15-0.5,1,0) -> 0 | V40: =MAX(D40-G40-L40,0)-O40 -> 0 | W40: =P40+$B$18 -> 37288.117
A41: 46692 | B41: =IF(A41<=$B$21,Budget!$F$70,Budget!$F$71)+IF(A41>$B$24,$B$25,0) -> 2503.0267 | C41: =IF(A41=$B$23,$B$22,0) -> 0 | D41: =B41+C41 -> 2503.0267 | E41: =H40 -> 0 | F41: =E41*$B$6/12 -> 0 | G41: =MIN(E41+F41,MAX(D41-K41,0)) -> 0 | H41: =E41+F41-G41 -> 0 | I41: =M40 -> 0 | J41: =I41*$B$8/12 -> 0 | K41: =MIN(I41+J41,J41+$B$9*I41) -> 0 | L41: =MIN(I41+J41,D41-G41) -> 0 | M41: =I41+J41-L41 -> 0 | N41: =P40 -> 21027.367 | O41: =MIN(MAX(D41-G41-L41,0),MAX($B$15-$B$18-N41,0)) -> 2503.0267 | P41: =N41+O41 -> 23530.394 | Q41: =IF(H41<=0.005,1,0) -> 1 | R41: =IF(M41<=0.005,1,0) -> 1 | S41: =IF(AND(Q41=1,R41=1),1,0) -> 1 | T41: =IF(P41>=$B$20,1,0) -> 0 | U41: =IF(P41+$B$18>=$B$15-0.5,1,0) -> 0 | V41: =MAX(D41-G41-L41,0)-O41 -> 0 | W41: =P41+$B$18 -> 39791.144
... A76: 47757 | B76: =IF(A76<=$B$21,Budget!$F$70,Budget!$F$71)+IF(A76>$B$24,$B$25,0) -> 2845.0267 | C76: =IF(A76=$B$23,$B$22,0) -> 0 | D76: =B76+C76 -> 2845.0267 | E76: =H75 -> 0 | F76: =E76*$B$6/12 -> 0 | G76: =MIN(E76+F76,MAX(D76-K76,0)) -> 0 | H76: =E76+F76-G76 -> 0 | I76: =M75 -> 0 | J76: =I76*$B$8/12 -> 0 | K76: =MIN(I76+J76,J76+$B$9*I76) -> 0 | L76: =MIN(I76+J76,D76-G76) -> 0 | M76: =I76+J76-L76 -> 0 | N76: =P75 -> 84581.25 | O76: =MIN(MAX(D76-G76-L76,0),MAX($B$15-$B$18-N76,0)) -> 0 | P76: =N76+O76 -> 84581.25 | Q76: =IF(H76<=0.005,1,0) -> 1 | R76: =IF(M76<=0.005,1,0) -> 1 | S76: =IF(AND(Q76=1,R76=1),1,0) -> 1 | T76: =IF(P76>=$B$20,1,0) -> 1 | U76: =IF(P76+$B$18>=$B$15-0.5,1,0) -> 1 | V76: =MAX(D76-G76-L76,0)-O76 -> 2845.0267 | W76: =P76+$B$18 -> 100842

Sheet Actuals
A1: Actuals by month — from the 12 statement CSVs (spend shown positive)
A2: Oct = Oct 1–13 only. Pending authorizations dated Oct 14–20 in the Checking export were excluded. Internal transfers, investment buys/sells and dividends excluded. Q-files used for completed quarters; 'Last 90' file used for Oct 1–13 only.
A4: Line | B4: Jan | C4: Feb | D4: Mar | E4: Apr | F4: May | G4: Jun | H4: Jul | I4: Aug | J4: Sep | K4: Oct* | L4: Jan–Sep total | M4: Jan–Sep avg | N4: Q3 avg
A5: INCOME (take-home deposits)
A6: Flagship payroll (all 3 accounts; Mar incl. ≈$38.9k bonus) | B6: 17767.46 | C6: 17292.97 | D6: 56680.72 | E6: 17796.97 | F6: 18589.52 | G6: 19357.91 | H6: 19331.52 | I6: 19331.5 | J6: 19331.51 | K6: 0 | L6: =SUM(B6:J6) -> 205480.08 | M6: =L6/9 -> 22831.12 | N6: =AVERAGE(H6:J6) -> 19331.51
A7: UMass payroll (Allison; all 3 accounts) | B7: 6410.38 | C7: 6410.38 | D7: 6381.15 | E7: 7306.35 | F7: 3245.11 | G7: 6370.6 | H7: 7963.28 | I7: 6622.78 | J7: 8161.68 | K7: 2280.02 | L7: =SUM(B7:J7) -> 58871.71 | M7: =L7/9 -> 6541.3011 | N7: =AVERAGE(H7:J7) -> 7582.58
A8: Other (checks received, $25k check 4/27, Venmo cashouts, card rewards) | B8: 1459.54 | C8: 3377.84 | D8: 0 | E8: 25235.81 | F8: 5247.42 | G8: 153.09 | H8: 132.58 | I8: 32.46 | J8: 486.2 | K8: 82.25 | L8: =SUM(B8:J8) -> 36124.94 | M8: =L8/9 -> 4013.8822 | N8: =AVERAGE(H8:J8) -> 217.08
A9: Subtotal | B9: =SUM(B6:B8) -> 25637.38 | C9: =SUM(C6:C8) -> 27081.19 | D9: =SUM(D6:D8) -> 63061.87 | E9: =SUM(E6:E8) -> 50339.13 | F9: =SUM(F6:F8) -> 27082.05 | G9: =SUM(G6:G8) -> 25881.6 | H9: =SUM(H6:H8) -> 27427.38 | I9: =SUM(I6:I8) -> 25986.74 | ... N9: =SUM(N6:N8) -> 27131.17
A11: CARD / STORE-CARD / LOAN-LINE PAYMENTS
A12: 'CARDMEMBER SERV' card | B12: 4300 | C12: 5520 | D12: 20305.96 | E12: 0 | F12: 10172.94 | G12: 0 | H12: 0 | I12: 0 | J12: 0 | K12: 0 | L12: =SUM(B12:J12) -> 40298.9 | M12: =L12/9 -> 4477.6556 | N12: =AVERAGE(H12:J12) -> 0
A13: JetBlue (Barclay) | B13: 32.71 | C13: 86.2 | D13: 11564.41 | E13: 0 | F13: 10344.77 | G13: 0 | H13: 567.01 | I13: 0 | J13: 84.46 | K13: 0 | L13: =SUM(B13:J13) -> 22679.56 | M13: =L13/9 -> 2519.9511 | N13: =AVERAGE(H13:J13) -> 217.15667
A14: Fidelity (Elan) | B14: 0 | C14: 0 | D14: 0 | E14: 0 | F14: 0 | G14: 0 | H14: 8397.68 | I14: 0 | J14: 250 | K14: 0 | L14: =SUM(B14:J14) -> 8647.68 | M14: =L14/9 -> 960.85333 | N14: =AVERAGE(H14:J14) -> 2882.56
A15: Apple Card | B15: 183.82 | C15: 0 | D15: 1286.9 | E15: 0 | F15: 38.29 | G15: 0 | H15: 0 | I15: 0 | J15: 0 | K15: 0 | L15: =SUM(B15:J15) -> 1509.01 | M15: =L15/9 -> 167.66778 | N15: =AVERAGE(H15:J15) -> 0
A16: Holyoke CU, Capital One, TD Retail, OnePay/Sync, Wells Fargo | B16: 500 | C16: 1709 | D16: 1175 | E16: 550 | F16: 2000 | G16: 1340 | H16: 0 | I16: 2350 | J16: 1849.62 | K16: 0 | L16: =SUM(B16:J16) -> 11473.62 | M16: =L16/9 -> 1274.8467 | N16: =AVERAGE(H16:J16) -> 1399.8733
A17: Subtotal | B17: =SUM(B12:B16) -> 5016.53 | C17: =SUM(C12:C16) -> 7315.2 | D17: =SUM(D12:D16) -> 34332.27 | E17: =SUM(E12:E16) -> 550 | F17: =SUM(F12:F16) -> 22556 | G17: =SUM(G12:G16) -> 1340 | H17: =SUM(H12:H16) -> 8964.69 | I17: =SUM(I12:I16) -> 2350 | ... N17: =SUM(N12:N16) -> 4499.59
A19: SPENDING (debit card, checks, autopays)
A20: Mortgage | B20: 6857.93 | C20: 6857.93 | D20: 6857.93 | E20: 6857.93 | F20: 6857.93 | G20: 6857.93 | H20: 6857.93 | I20: 6857.93 | J20: 6857.93 | K20: 6857.93 | L20: =SUM(B20:J20) -> 61721.37 | M20: =L20/9 -> 6857.93 | N20: =AVERAGE(H20:J20) -> 6857.93
A21: Volvo loan (Metro CU) | B21: 1173.99 | C21: 1173.99 | D21: 1173.99 | E21: 1173.99 | F21: 1173.99 | G21: 1173.99 | H21: 1173.99 | I21: 1173.99 | J21: 1173.99 | K21: 1173.99 | L21: =SUM(B21:J21) -> 10565.91 | M21: =L21/9 -> 1173.99 | N21: =AVERAGE(H21:J21) -> 1173.99
A22: Audi loan | B22: 1057.39 | C22: 1057.39 | D22: 1057.39 | E22: 1057.39 | F22: 1057.39 | G22: 1057.39 | H22: 1057.39 | I22: 1057.39 | J22: 1057.39 | K22: 0 | L22: =SUM(B22:J22) -> 9516.51 | M22: =L22/9 -> 1057.39 | N22: =AVERAGE(H22:J22) -> 1057.39
A23: Synchrony installment | B23: 341.99 | C23: 341.99 | D23: 341.99 | E23: 341.99 | F23: 341.99 | G23: 341.99 | H23: 341.99 | I23: 341.99 | J23: 341.99 | K23: 0 | L23: =SUM(B23:J23) -> 3077.91 | M23: =L23/9 -> 341.99 | N23: =AVERAGE(H23:J23) -> 341.99
A24: Student loan (one payment, Feb) | B24: 0 | C24: 408.76 | D24: 0 | E24: 0 | F24: 0 | G24: 0 | H24: 0 | I24: 0 | J24: 0 | K24: 0 | L24: =SUM(B24:J24) -> 408.76 | M24: =L24/9 -> 45.417778 | N24: =AVERAGE(H24:J24) -> 0
A25: GEICO | B25: 856.83 | C25: 857.23 | D25: 857.23 | E25: 857.23 | F25: 857.23 | G25: 857.25 | H25: 818.67 | I25: 819.07 | J25: 819.07 | K25: 819.07 | L25: =SUM(B25:J25) -> 7599.81 | M25: =L25/9 -> 844.42333 | N25: =AVERAGE(H25:J25) -> 818.93667
A26: MassMutual + Lincoln National | B26: 286.67 | C26: 0 | D26: 573.34 | E26: 1402.6 | F26: 286.67 | G26: 286.67 | H26: 286.67 | I26: 286.67 | J26: 286.67 | K26: 0 | L26: =SUM(B26:J26) -> 3695.96 | M26: =L26/9 -> 410.66222 | N26: =AVERAGE(H26:J26) -> 286.67
A27: Heating oil / Petro | B27: 614 | C27: 614 | D27: 614 | E27: 614 | F27: 614 | G27: 614 | H27: 1855.6 | I27: 949 | J27: 949 | K27: 0 | L27: =SUM(B27:J27) -> 7437.6 | M27: =L27/9 -> 826.4 | N27: =AVERAGE(H27:J27) -> 1251.2
A28: Electric | B28: 323.39 | C28: 286.52 | D28: 152.98 | E28: 134.4 | F28: 176.88 | G28: 212.36 | H28: 357.41 | I28: 422.56 | J28: 335.36 | K28: 0 | L28: =SUM(B28:J28) -> 2401.86 | M28: =L28/9 -> 266.87333 | N28: =AVERAGE(H28:J28) -> 371.77667
A29: Water + trash | B29: 368.15 | C29: 0 | D29: 0 | E29: 524.1 | F29: 0 | G29: 0 | H29: 376.08 | I29: 0 | J29: 0 | K29: 557.77 | L29: =SUM(B29:J29) -> 1268.33 | M29: =L29/9 -> 140.92556 | N29: =AVERAGE(H29:J29) -> 125.36
A30: Verizon | B30: 400.62 | C30: 400.57 | D30: 400.57 | E30: 400.57 | F30: 635.47 | G30: 385.27 | H30: 364.91 | I30: 346.53 | J30: 346.53 | K30: 256.54 | L30: =SUM(B30:J30) -> 3681.04 | M30: =L30/9 -> 409.00444 | N30: =AVERAGE(H30:J30) -> 352.65667
A31: SiriusXM / WGBH / E-ZPass | B31: 134.97 | C31: 94.97 | D31: 137.97 | E31: 263.07 | F31: 137.97 | G31: 137.97 | H31: 137.97 | I31: 97.97 | J31: 137.97 | K31: 25 | L31: =SUM(B31:J31) -> 1280.83 | M31: =L31/9 -> 142.31444 | N31: =AVERAGE(H31:J31) -> 124.63667
... A58: Unclassified | B58: 127.73 | C58: 368.99 | D58: 82.91 | E58: 368.97 | F58: 138.04 | G58: 0 | H58: 267.33 | I58: 210.76 | J58: 0 | K58: 0 | L58: =SUM(B58:J58) -> 1564.73 | M58: =L58/9 -> 173.85889 | N58: =AVERAGE(H58:J58) -> 159.36333
A59: Subtotal | B59: =SUM(B20:B58) -> 19667.52 | C59: =SUM(C20:C58) -> 20404.67 | D59: =SUM(D20:D58) -> 22107.12 | E59: =SUM(E20:E58) -> 22357.78 | F59: =SUM(F20:F58) -> 21917.94 | G59: =SUM(G20:G58) -> 24898.9 | H59: =SUM(H20:H58) -> 23087.05 | I59: =SUM(I20:I58) -> 20554.52 | ... N59: =SUM(N20:N58) -> 22269.753
A61: Total outflow incl. card/loan-line payments | B61: =B17+B59 -> 24684.05 | C61: =C17+C59 -> 27719.87 | D61: =D17+D59 -> 56439.39 | E61: =E17+E59 -> 22907.78 | F61: =F17+F59 -> 44473.94 | G61: =G17+G59 -> 26238.9 | H61: =H17+H59 -> 32051.74 | I61: =I17+I59 -> 22904.52 | ... N61: =N17+N59 -> 26769.343
A62: Total income | B62: =B9 -> 25637.38 | C62: =C9 -> 27081.19 | D62: =D9 -> 63061.87 | E62: =E9 -> 50339.13 | F62: =F9 -> 27082.05 | G62: =G9 -> 25881.6 | H62: =H9 -> 27427.38 | I62: =I9 -> 25986.74 | ... N62: =N9 -> 27131.17
A63: Income − outflow (before investing/transfers) | B63: =B62-B61 -> 953.33 | C63: =C62-C61 -> -638.68 | D63: =D62-D61 -> 6622.48 | E63: =E62-E61 -> 27431.35 | F63: =F62-F61 -> -17391.89 | G63: =G62-G61 -> -357.3 | H63: =H62-H61 -> -4624.36 | I63: =I62-I61 -> 3082.22 | ... N63: =N62-N61 -> 361.82667

Sheet Subscriptions
A1: Subscription & recurring-charge audit
A2: From Checking/Bills statements Jan 1–Oct 13. 'Action' (blue) is my suggested default — change it; savings recalc. Cut = full annual savings; Review/Keep = $0 counted.
A4: Service | B4: Cadence | C4: Typical charge | D4: Annualized | E4: Action | F4: Annual savings if cut | G4: Last seen | H4: Note
A5: SiriusXM | B5: Monthly | C5: 72.97 | D5: =IF(B5="Monthly",C5*12,IF(B5="Semiannual",C5*2,C5)) -> 875.64 | E5: Keep | F5: =IF(E5="Cut",D5,0) -> 0 | G5: 2026-09-24 | H5: Keeping (your call). Paid from Bills account.
A6: YouTube TV | B6: Monthly | C6: 82.99 | D6: =IF(B6="Monthly",C6*12,IF(B6="Semiannual",C6*2,C6)) -> 995.88 | E6: Review | F6: =IF(E6="Cut",D6,0) -> 0 | G6: 2026-10-01 | H6: Largest streaming line. Compare with Netflix/Hulu usage.
A7: Netflix | B7: Monthly | C7: 26.99 | D7: =IF(B7="Monthly",C7*12,IF(B7="Semiannual",C7*2,C7)) -> 323.88 | E7: Keep | F7: =IF(E7="Cut",D7,0) -> 0 | G7: 2026-10-08
A8: Hulu | B8: Monthly | C8: 18.99 | D8: =IF(B8="Monthly",C8*12,IF(B8="Semiannual",C8*2,C8)) -> 227.88 | E8: Review | F8: =IF(E8="Cut",D8,0) -> 0 | G8: 2026-10-07 | H8: Overlaps YouTube TV's Hulu/live offering? Check.
A9: Spotify | B9: Monthly | C9: 12.99 | D9: =IF(B9="Monthly",C9*12,IF(B9="Semiannual",C9*2,C9)) -> 155.88 | E9: Keep | F9: =IF(E9="Cut",D9,0) -> 0 | G9: 2026-09-22
A10: Amazon Prime (annual) | B10: Annual | C10: 139 | D10: =IF(B10="Monthly",C10*12,IF(B10="Semiannual",C10*2,C10)) -> 139 | E10: Keep | F10: =IF(E10="Cut",D10,0) -> 0 | G10: 2026-09-21 | H10: Charged 9/21. Plus a $4.99 monthly Prime charge — verify what it is.
A11: Amazon Prime monthly add-on | B11: Monthly | C11: 4.99 | D11: =IF(B11="Monthly",C11*12,IF(B11="Semiannual",C11*2,C11)) -> 59.88 | E11: Review | F11: =IF(E11="Cut",D11,0) -> 0 | G11: 2026-09-28 | H11: Likely a channel add-on.
A12: Amazon Kids+ (FreeTime) | B12: Monthly | C12: 6.36 | D12: =IF(B12="Monthly",C12*12,IF(B12="Semiannual",C12*2,C12)) -> 76.32 | E12: Review | F12: =IF(E12="Cut",D12,0) -> 0 | G12: 2026-09-28 | H12: $6.36 → $8.49 in Sep.
A13: Kindle Unlimited | B13: Monthly | C13: 11.99 | D13: =IF(B13="Monthly",C13*12,IF(B13="Semiannual",C13*2,C13)) -> 143.88 | E13: Review | F13: =IF(E13="Cut",D13,0) -> 0 | G13: 2026-09-15 | H13: Overlaps Audible — keep one.
A14: Audible | B14: Monthly | C14: 8.99 | D14: =IF(B14="Monthly",C14*12,IF(B14="Semiannual",C14*2,C14)) -> 107.88 | E14: Review | F14: =IF(E14="Cut",D14,0) -> 0 | G14: 2026-10-05 | H14: Was $14.95; now $8.99.
A15: NYTimes | B15: Monthly | C15: 25 | D15: =IF(B15="Monthly",C15*12,IF(B15="Semiannual",C15*2,C15)) -> 300 | E15: Review | F15: =IF(E15="Cut",D15,0) -> 0 | G15: 2026-09-24 | H15: $25–$30/mo.
A16: Boston Globe | B16: Monthly | C16: 27.72 | D16: =IF(B16="Monthly",C16*12,IF(B16="Semiannual",C16*2,C16)) -> 332.64 | E16: Review | F16: =IF(E16="Cut",D16,0) -> 0 | G16: 2026-09-28 | H16: Two daily-news subs + Atlantic + Medium.
A17: The Atlantic | B17: Annual | C17: 99.99 | D17: =IF(B17="Monthly",C17*12,IF(B17="Semiannual",C17*2,C17)) -> 99.99 | E17: Review | F17: =IF(E17="Cut",D17,0) -> 0 | G17: 2026-03-30
A18: Medium | B18: Annual | C18: 150 | D18: =IF(B18="Monthly",C18*12,IF(B18="Semiannual",C18*2,C18)) -> 150 | E18: Review | F18: =IF(E18="Cut",D18,0) -> 0 | G18: 2026-03-03
A19: ProPublica (donation) | B19: Monthly | C19: 20.7 | D19: =IF(B19="Monthly",C19*12,IF(B19="Semiannual",C19*2,C19)) -> 248.4 | E19: Keep | F19: =IF(E19="Cut",D19,0) -> 0 | G19: 2026-09-15 | H19: Charitable — your call.
A20: Patreon | B20: Monthly | C20: 10 | D20: =IF(B20="Monthly",C20*12,IF(B20="Semiannual",C20*2,C20)) -> 120 | E20: Keep | F20: =IF(E20="Cut",D20,0) -> 0 | G20: 2026-10-05 | H20: $5 + $10 charges.
A21: Ancestry | B21: Monthly | C21: 32.99 | D21: =IF(B21="Monthly",C21*12,IF(B21="Semiannual",C21*2,C21)) -> 395.88 | E21: Review | F21: =IF(E21="Cut",D21,0) -> 0 | G21: 2026-09-29 | H21: $396/yr. Pause between research bursts.
A22: PayPal 'Noslusomund' | B22: Monthly | C22: 13.94 | D22: =IF(B22="Monthly",C22*12,IF(B22="Semiannual",C22*2,C22)) -> 167.28 | E22: Review | F22: =IF(E22="Cut",D22,0) -> 0 | G22: 2026-10-02 | H22: Unrecognized merchant name — verify what it is.
A23: Daniels Table | B23: Monthly | C23: 20.76 | D23: =IF(B23="Monthly",C23*12,IF(B23="Semiannual",C23*2,C23)) -> 249.12 | E23: Review | F23: =IF(E23="Cut",D23,0) -> 0 | G23: 2026-09-16 | H23: Verify what it is.
A24: GitHub | B24: Monthly | C24: 10.63 | D24: =IF(B24="Monthly",C24*12,IF(B24="Semiannual",C24*2,C24)) -> 127.56 | E24: Keep | F24: =IF(E24="Cut",D24,0) -> 0 | G24: 2026-10-06
A25: Claude (Anthropic) | B25: Monthly | C25: 21.25 | D25: =IF(B25="Monthly",C25*12,IF(B25="Semiannual",C25*2,C25)) -> 255 | E25: Keep | F25: =IF(E25="Cut",D25,0) -> 0 | G25: 2026-10-02
A26: Whoop | B26: Annual | C26: 381.44 | D26: =IF(B26="Monthly",C26*12,IF(B26="Semiannual",C26*2,C26)) -> 381.44 | E26: Keep | F26: =IF(E26="Cut",D26,0) -> 0 | G26: 2026-05-26 | H26: Renewal charged May; also $349.67 in Jul (upgrade/second device?).
A27: Ring plan | B27: Annual | C27: 212.49 | D27: =IF(B27="Monthly",C27*12,IF(B27="Semiannual",C27*2,C27)) -> 212.49 | E27: Review | F27: =IF(E27="Cut",D27,0) -> 0 | G27: 2026-09-08 | H27: AI Pro plan $212.49 (Sep); Basic was $49.99 in Jan. Downgrade?
A28: Calendly | B28: Semiannual | C28: 114.75 | D28: =IF(B28="Monthly",C28*12,IF(B28="Semiannual",C28*2,C28)) -> 229.5 | E28: Review | F28: =IF(E28="Cut",D28,0) -> 0 | G28: 2026-06-15 | H28: $102 (Mar) and $127.50 (Jun).
A29: ZenBusiness | B29: Annual | C29: 548 | D29: =IF(B29="Monthly",C29*12,IF(B29="Semiannual",C29*2,C29)) -> 548 | E29: Keep | F29: =IF(E29="Cut",D29,0) -> 0 | G29: 2026-04-02 | H29: Business entity annual fee (X2 venture?).
A30: Raddish Kids | B30: Monthly | C30: 32.95 | D30: =IF(B30="Monthly",C30*12,IF(B30="Semiannual",C30*2,C30)) -> 395.4 | E30: Review | F30: =IF(E30="Cut",D30,0) -> 0 | G30: 2026-05-29 | H30: Last charge May — confirm it was cancelled.
A31: CrunchLabs | B31: Monthly | C31: 115.23 | D31: =IF(B31="Monthly",C31*12,IF(B31="Semiannual",C31*2,C31)) -> 1382.76 | E31: Review | F31: =IF(E31="Cut",D31,0) -> 0 | G31: 2026-09-28 | H31: $34.77 → $115 → $130. Check which plan/crate.
A32: WGBH | B32: Monthly | C32: 25 | D32: =IF(B32="Monthly",C32*12,IF(B32="Semiannual",C32*2,C32)) -> 300 | E32: Keep | F32: =IF(E32="Cut",D32,0) -> 0 | G32: 2026-10-13 | H32: Public-media donation.
A33: Total recurring (annualized) | D33: =SUM(D5:D32) -> 9001.58 | F33: =SUM(F5:F32) -> 0
A34: Annualized, if every 'Review' item were cut (upper bound) | D34: =SUMIF(E5:E32,"Review",D5:D32) -> 5526.78
A36: Not in this list but bigger: Apple.com/bill (90 charges, $3,441 YTD; Q3 avg $572/mo vs ~$275 in H1), Nintendo/PlayStation ($935 YTD, $598 in Aug), Greenlight reloads ($1,307 YTD). These are the kids' digital spend — see Budget row 'Kids digital'.

Sheet Rules & Legend
A1: How to live by this budget
A3: Colors | B3: Blue = input/assumption you can change. Black = formula. Green = link from another sheet. Yellow/green fill = key results.
A4: Three accounts, three jobs | B4: Bills = autopay fixed obligations only. Checking = debit-card envelopes only. SPAXX = savings engine. The paycheck split on the Budget sheet is what makes each account's inflow equal its budget.
A5: No new card charges | B5: Pull JetBlue/Fidelity (and store cards) out of wallets, Apple Pay, Amazon, DoorDash, Apple ID. Cards exist only to be paid down until cleared.
A6: Lumpy costs get a sinking fund | B6: Travel, gifts, car/home repair, annual premiums, Patriots tickets — if it has a due date or a season, it has a monthly line. Sinking balances do NOT count toward the emergency fund.
A7: Payoff mechanics | B7: Autopay the minimum on every card. On each payday, send the Phase paydown amount to JetBlue (29.74%) until zero, then Fidelity (17.49%). Pay only the scheduled amount on the HELOC (Holyoke, now 7%, ~$1,100/mo 10-year P&I) and the 0% loans (Synchrony AC, Wells Fargo plumbing) while a 29.74% or 17.49% balance exists.
A8: 5th-paycheck months | B8: Allison is paid weekly: four months a year have five paychecks (2026: Apr, Jul, Sep, Dec). Budget on 52/12; the extra paycheck goes straight to card paydown/EF.
A9: Weekly 10-minute check (Sunday) | B9: Four numbers against the Weekly Envelopes sheet: groceries, dining + takeout, gas, Amazon.
A10: Protected 'joy' lines | B10: Thoreau Club, kids' activities, dining out, entertainment/hobbies, donations, family trips. These are funded first and not cut — the cuts come from app-store/gaming, Amazon, overlapping subscriptions, and insurance/phone/oil shopping. Takeout and SiriusXM are kept.
A11: Investing | B11: Phase 1 = no new investment dollars (your config rule). Dividend reinvestment is fine. Revisit when cards are cleared and EF is at target.
A12: Monthly reset | B12: Last Sunday of the month: update Actuals, re-run the plan, adjust targets.
A14: Assumptions & sources
A15: • | B15: Income: Sep 2026 payroll deposits across the three accounts (statements).
A16: • | B16: Debt balances: Kevin config debt tracker dated 2026-09-27 (JetBlue $9,800.78; Fidelity $5,341.52). APRs: 'Debt consolidation' note (JetBlue 29.74%, Fidelity 17.49%, HELOC 3.5% in the note — now 7% with ~$1,100 minimum per you, Volvo 5.49%, Audi 5.25%, Petro AC loan 0%). That note's balances are older than the config.
A17: • | B17: Emergency fund $12,081 (SPAXX $9,501 + lifestyle $2,580) is from config 9/27 — the CSVs contain no balances, so I could not verify it.
A18: • | B18: Sinking-fund amounts (travel $500, gifts $250, repair $200) are placeholders sized to replace card spend I cannot see; calibrate with card statements.
A19: • | B19: Card charges are not in the statements — only payments are. The plan assumes zero new card charges.
A20: • | B20: Categories are keyword-based on merchant strings; unclassified items are shown on Actuals. Weekly checks = cleaning help ($160/wk); DoorDash/Grubhub = family takeout (per you). HELOC payment of ~$1,100 is assumed from Nov-26. Synchrony = 0% AC-repair loan; Wells Fargo = 0% plumbing loan, assumed $450/mo (one payment seen).
A21: • | B21: Not financial, tax, or legal advice.
